Workbook

Sheet 🏆 SUMMARY
A1: MF INTELLIGENCE — ASSET CLASS RANKED SUMMARY
A2: ="Top Performer per Asset Class | 55% Momentum + 45% Quality | Total Asset Classes: "&COUNTA(B5:B11)&" | ⭐ Strong Buy+: "&COUNTIF(Q5:Q11,"*Strong*")
F3: ◄ Momentum ► | I3: ◄ Long-Term ► | L3: ◄ Engine Scores ► | O3: ◄ Signals ►
A4: Rank | B4: Asset Class | C4: Top Scheme | D4: AMC | E4: Category | F4: 1M Return | G4: 3M Return | H4: 6M Return | I4: 1Y Return | J4: 2Y CAGR | K4: 3Y CAGR | L4: Engine 1 (Momentum) | M4: Engine 2 (Quality) | N4: Composite Score | O4: Momentum Signal | P4: Quality Signal | Q4: Composite Signal
A5: 1 | B5: Aggressive Hybrid Fund | C5: BANK OF INDIA MID & SMALL CAP EQUITY & DEBT FUND - REGULAR PLAN GROWTH | D5: Bank of India Mutual Fund | E5: Aggressive Hybrid Fund | F5: 2.99 | G5: 7.47 | H5: 11.66 | I5: 15 | J5: 5.5035544 | K5: 63.04 | L5: 100 | M5: 0 | N5: 55 | O5: 🔥 Hot | P5: 🔴 Not Qualified | Q5: ✅ Buy
A6: 2 | B6: Arbitrage Fund | C6: Kotak Arbitrage Fund - Regular Plan - Growth | D6: Kotak Mahindra Mutual Fund | E6: Arbitrage Fund | F6: 0.44 | G6: 1.48 | H6: 2.9 | I6: 5.97 | J6: 6.4142848 | K6: 22.17 | L6: 88.3 | M6: 0 | N6: 48.6 | O6: ⭐ Strong | P6: 🔴 Not Qualified | Q6: ⚠️ Watch
A7: 3 | B7: Balanced Hybrid Fund | C7: 360 ONE Balanced Hybrid Fund - Regular Plan - Growth | D7: 360 ONE Mutual Fund | E7: Balanced Hybrid Fund | F7: 0.39 | G7: 5.11 | H7: 3.89 | I7: 5.5 | J7: 4.0865025 | K7: 0 | L7: 77.5 | M7: 0 | N7: 42.6 | O7: ⭐ Strong | P7: ⏳ New Fund | Q7: 📈 Momentum Only
A8: 4 | B8: Conservative Hybrid Fund | C8: Nippon India Conservative Hybrid Fund-Growth Plan | D8: Nippon India Mutual Fund | E8: Conservative Hybrid Fund | F8: 0.79 | G8: 2.99 | H8: 2.56 | I8: 7.22 | J8: 7.5313908 | K8: 26.82 | L8: 87.8 | M8: 0 | N8: 48.3 | O8: ⭐ Strong | P8: 🔴 Not Qualified | Q8: ⚠️ Watch
A9: 5 | B9: Dynamic Asset Allocation Or Balanced Advantage | C9: ICICI Prudential Balanced Advantage Fund - Growth | D9: ICICI Prudential Mutual Fund | E9: Dynamic Asset Allocation Or Balanced Advantage | F9: 2.24 | G9: 6.21 | H9: 2.53 | I9: 8.44 | J9: 7.2427154 | K9: 41.27 | L9: 93.2 | M9: 0 | N9: 51.3 | O9: 🔥 Hot | P9: 🔴 Not Qualified | Q9: ⚠️ Watch
A10: 6 | B10: Equity Savings | C10: Edelweiss Equity Savings Fund - Regular Plan - Growth Option | D10: Edelweiss Mutual Fund | E10: Equity Savings | F10: 1.34 | G10: 3.73 | H10: 4.13 | I10: 8.12 | J10: 7.856386 | K10: 35.86 | L10: 99.5 | M10: 0 | N10: 54.8 | O10: 🔥 Hot | P10: 🔴 Not Qualified | Q10: ⚠️ Watch
A11: 7 | B11: Multi Asset Allocation | C11: Nippon India Multi Asset Allocation Fund - Regular Plan - Growth Option | D11: Nippon India Mutual Fund | E11: Multi Asset Allocation | F11: 3.11 | G11: 4.03 | H11: 2.85 | I11: 17.08 | J11: 13.274004 | K11: 69.63 | L11: 87.5 | M11: 75 | N11: 81.9 | O11: ⭐ Strong | P11: ⭐ Strong | Q11: ⭐ Strong Buy

Sheet 📋 ASSUMPTIONS
A1: DUAL ENGINE MODEL — COMPLETE METHODOLOGY & ASSUMPTIONS
A2: Generated: 2026-10-16 22:56:14 | Comprehensive Documentation | All Values Numeric (0 = Missing)
A4: 🔍 DATA FILTERS (Pre-Processing)
A5: Filter Parameter | B5: Value | C5: Description | D5: Python Logic
A6: cat_level_1 | B6: Open Ended Schemes | C6: Scheme category level 1 | D6: df[col] == value
A7: cat_level_2 | B7: Other Scheme | C7: Scheme category level 2 | D7: df[col] == value
A8: plan_type | B8: Regular | C8: Regular plans only (not Direct) | D8: df[col] == value
A9: option_type | B9: Growth | C9: Growth option only | D9: df[col] == value
A11: 📋 COLUMN MAPPING (Source → Internal)
A12: Internal Name | B12: Source Column | C12: Data Type | D12: Notes
A13: scheme_name | B13: scheme_name | C13: String | D13: Fund name for display
A14: category | B14: cat_level_3 | C14: String | D14: Category for grouping
A15: amc | B15: amc_name | C15: String | D15: Asset Management Company
A16: return_1m | B16: return_30d | C16: Numeric % | D16: 30-day return
A17: return_3m | B17: return_90d | C17: Numeric % | D17: 90-day return
A18: return_6m | B18: return_180d | C18: Numeric % | D18: 180-day return
A19: return_1y | B19: return_365d | C19: Numeric % | D19: 365-day return
A20: return_2y | B20: return_730d | C20: Numeric % | D20: 730-day cumulative → CAGR
A21: return_3y | B21: return_1095d | C21: Numeric % | D21: 1095-day CAGR
A23: 📊 DATA STATUS CLASSIFICATION
A24: Status | B24: Condition | C24: Visual Style | D24: Scoring Impact
A25: ✅ FULL | B25: All 1M/3M/6M + 2Y/3Y present | C25: White/Ranked Colors | D25: Both E1 and E2 calculated
A26: ⚠️ MOMENTUM_ONLY | B26: 1M/3M/6M present, 2Y/3Y missing | C26: Light Amber + Italic | D26: Only E1 calculated, E2=0
A27: ❌ MISSING | B27: Missing any of 1M/3M/6M | C27: Light Gray + Italic | D27: E1=0, E2=0, Comp=0
A29: 🚦 QUALITY GATES (Engine 2 Eligibility)
A30: Gate | B30: Threshold | C30: Formula | D30: Purpose
A31: Min 2Y CAGR | B31: 10% | C31: r2y_cagr > 10% | D31: Filter low long-term performers
A32: Min 3Y CAGR | B32: 12% | C32: r3y > 12% | D32: Filter inconsistent performers
A33: Drawdown Tolerance | B33: -30% | C33: r1y > -30% | D33: Exclude extreme losers
A34: Data Status | B34: FULL only | C34: data_status == 'FULL' | D34: Only complete data qualifies
A36: 📈 ENGINE 1: MOMENTUM SCORE (Short-Term)
A37: Component | B37: Weight | C37: Formula | D37: Description
A38: 6M Return Rank | B38: 30% | C38: pct_rank(r6m) × 0.30 | D38: 6-month percentile within category
A39: 3M Return Rank | B39: 20% | C39: pct_rank(r3m) × 0.20 | D39: 3-month percentile within category
A40: 1Y Return Rank | B40: 25% | C40: pct_rank(r1y) × 0.25 | D40: 1-year percentile within category
A41: 1M Return Rank | B41: 25% | C41: pct_rank(r1m) × 0.25 | D41: 1-month percentile within category
A42: Trend Bonus | B42: +5.0 | C42: If r6m > r3m > r1m | D42: 📈 Uptrend bonus (0 to 5 pts)
A43: Final E1 | B43: 0-100 | C43: clip(sum + trend, 0, 100) | D43: Capped percentile score
A45: 🏛️ ENGINE 2: QUALITY SCORE (Long-Term)
A46: Component | B46: Weight | C46: Formula | D46: Description
...

Sheet Aggressive Hybrid Fund
A1: ✦ AGGRESSIVE HYBRID FUND ✦
A2: ="Dual Engine: 55% Momentum + 45% Quality | ✅ Full: "&COUNTIF(Q5:Q32,"FULL")&" | ⚠️ Momentum: "&COUNTIF(Q5:Q32,"MOMENTUM_ONLY")&" | ❌ Missing: "&COUNTIF(Q5:Q32,"MISSING")&" | Total: "&COUNTA(B5:B32)
E3: ◄ Momentum ► | H3: ◄ Long-Term ► | K3: ◄ Engine Scores ► | N3: ◄ Signals ►
A4: Rank | B4: Scheme Name | C4: AMC | D4: Asset Class | E4: 1M Return | F4: 3M Return | G4: 6M Return | H4: 1Y Return | I4: 2Y CAGR | J4: 3Y CAGR | K4: Engine 1 (Momentum) | L4: Engine 2 (Quality) | M4: Composite Score | N4: Momentum Signal | O4: Quality Signal | P4: Composite Signal | Q4: Data Status
A5: 1 | B5: BANK OF INDIA MID & SMALL CAP EQUITY & DEBT FUND - REGULAR PLAN GROWTH | C5: Bank of India Mutual Fund | D5: Aggressive Hybrid Fund | E5: 2.99 | F5: 7.47 | G5: 11.66 | H5: 15 | I5: 5.5035544 | J5: 63.04 | K5: 100 | L5: 0 | M5: 55 | N5: 🔥 Hot | O5: 🔴 Not Qualified | P5: ✅ Buy | Q5: FULL
A6: 2 | B6: Navi Aggressive Hybrid Fund - Regular Plan - Growth | C6: Navi Mutual Fund | D6: Aggressive Hybrid Fund | E6: 2.45 | F6: 8.71 | G6: 6.51 | H6: 10.71 | I6: 5.446669 | J6: 37.75 | K6: 95.4 | L6: 0 | M6: 52.5 | N6: 🔥 Hot | O6: 🔴 Not Qualified | P6: ⚠️ Watch | Q6: FULL
A7: 3 | B7: LIC MF Aggressive Hybrid Fund-Regular Plan-Growth | C7: LIC Mutual Fund | D7: Aggressive Hybrid Fund | E7: 3.72 | F7: 7.17 | G7: 3.77 | H7: 5.46 | I7: 3.4263023 | J7: 39.39 | K7: 90.8 | L7: 0 | M7: 49.9 | N7: 🔥 Hot | O7: 🔴 Not Qualified | P7: ⚠️ Watch | Q7: FULL
A8: 4 | B8: Bandhan Aggressive Hybrid Fund-Regular Plan Growth | C8: Bandhan Mutual Fund | D8: Aggressive Hybrid Fund | E8: 2.04 | F8: 6.98 | G8: 3.55 | H8: 9.58 | I8: 7.9953703 | J8: 50.07 | K8: 88.8 | L8: 0 | M8: 48.9 | N8: ⭐ Strong | O8: 🔴 Not Qualified | P8: ⚠️ Watch | Q8: FULL
A9: 5 | B9: Union Aggressive Hybrid Fund - Regular Plan - Growth Option | C9: Union Mutual Fund | D9: Aggressive Hybrid Fund | E9: 1.24 | F9: 6.44 | G9: 1.89 | H9: 5.55 | I9: 4 | J9: 36.75 | K9: 73.1 | L9: 0 | M9: 40.2 | N9: 📈 Good | O9: 🔴 Not Qualified | P9: ⚠️ Watch | Q9: FULL
A10: 6 | B10: JM Aggressive Hybrid Fund (Regular) -Growth Option | C10: JM Financial Mutual Fund | D10: Aggressive Hybrid Fund | E10: 2.97 | F10: 6.5 | G10: 2.23 | H10: 3.49 | I10: -1.9489929 | J10: 44.34 | K10: 73.1 | L10: 0 | M10: 40.2 | N10: 📈 Good | O10: 🔴 Not Qualified | P10: ⚠️ Watch | Q10: FULL
A11: 7 | B11: Kotak Aggressive Hybrid Fund - Regular Plan -Growth | C11: Kotak Mahindra Mutual Fund | D11: Aggressive Hybrid Fund | E11: 1.17 | F11: 5.18 | G11: 2.37 | H11: 6.01 | I11: 4.3695358 | J11: 44.68 | K11: 70.4 | L11: 0 | M11: 38.7 | N11: 📈 Good | O11: 🔴 Not Qualified | P11: 🔴 Avoid | Q11: FULL
A12: 8 | B12: SBI EQUITY HYBRID FUND - REGULAR PLAN -Growth | C12: SBI Mutual Fund | D12: Aggressive Hybrid Fund | E12: 0.74 | F12: 4.22 | G12: 3.04 | H12: 6.64 | I12: 7.6661507 | J12: 44.83 | K12: 64.4 | L12: 0 | M12: 35.4 | N12: 📈 Good | O12: 🔴 Not Qualified | P12: 🔴 Avoid | Q12: FULL
A13: 9 | B13: CANARA ROBECO EQUITY HYBRID FUND - REGULAR PLAN - GROWTH OPTION | C13: Canara Robeco Mutual Fund | D13: Aggressive Hybrid Fund | E13: 1.63 | F13: 4.96 | G13: 0.5 | H13: 4.4 | I13: 3.5857133 | J13: 38.37 | K13: 61.5 | L13: 0 | M13: 33.8 | N13: 📈 Good | O13: 🔴 Not Qualified | P13: 🔴 Avoid | Q13: FULL
A14: 10 | B14: Edelweiss Aggressive Hybrid Fund- Plan B-Growth Option | C14: Edelweiss Mutual Fund | D14: Aggressive Hybrid Fund | E14: 1.66 | F14: 4.28 | G14: 1.34 | H14: 4.38 | I14: 3.7641557 | J14: 45.49 | K14: 60.6 | L14: 0 | M14: 33.3 | N14: 📈 Good | O14: 🔴 Not Qualified | P14: 🔴 Avoid | Q14: FULL
A15: 11 | B15: Edelweiss Aggressive Hybrid Fund - Regular Plan - Growth Option | C15: Edelweiss Mutual Fund | D15: Aggressive Hybrid Fund | E15: 1.66 | F15: 4.29 | G15: 1.33 | H15: 4.38 | I15: 3.754518 | J15: 45.34 | K15: 60.2 | L15: 0 | M15: 33.1 | N15: 📈 Good | O15: 🔴 Not Qualified | P15: 🔴 Avoid | Q15: FULL
A16: 12 | B16: quant Aggressive Hybrid Fund - Growth Option - Regular Plan | C16: quant Mutual Fund | D16: Aggressive Hybrid Fund | E16: -1.81 | F16: 3.24 | G16: 8.06 | H16: 11.91 | I16: 3.3731106 | J16: 44.36 | K16: 59.4 | L16: 0 | M16: 32.7 | N16: ➡️ Neutral | O16: 🔴 Not Qualified | P16: 🔴 Avoid | Q16: FULL
... A32: 0 | B32: Nippon India Aggressive Hybrid Fund - Segregated Portfolio 2 - Growth Plan | C32: Nippon India Mutual Fund | D32: Aggressive Hybrid Fund | E32: 0 | F32: 0 | G32: 0 | H32: 0 | I32: 0 | J32: 0 | K32: 0 | L32: 0 | M32: 0 | N32: ❌ N/A | O32: ❌ N/A | P32: ❌ Missing Data | Q32: MISSING

Sheet Arbitrage Fund
A1: ✦ ARBITRAGE FUND ✦
A2: ="Dual Engine: 55% Momentum + 45% Quality | ✅ Full: "&COUNTIF(Q5:Q38,"FULL")&" | ⚠️ Momentum: "&COUNTIF(Q5:Q38,"MOMENTUM_ONLY")&" | ❌ Missing: "&COUNTIF(Q5:Q38,"MISSING")&" | Total: "&COUNTA(B5:B38)
E3: ◄ Momentum ► | H3: ◄ Long-Term ► | K3: ◄ Engine Scores ► | N3: ◄ Signals ►
A4: Rank | B4: Scheme Name | C4: AMC | D4: Asset Class | E4: 1M Return | F4: 3M Return | G4: 6M Return | H4: 1Y Return | I4: 2Y CAGR | J4: 3Y CAGR | K4: Engine 1 (Momentum) | L4: Engine 2 (Quality) | M4: Composite Score | N4: Momentum Signal | O4: Quality Signal | P4: Composite Signal | Q4: Data Status
A5: 1 | B5: quant Arbitrage Fund - Growth Option - Regular Plan | C5: quant Mutual Fund | D5: Arbitrage Fund | E5: 0.44 | F5: 1.63 | G5: 3.35 | H5: 6.85 | I5: 0 | J5: 0 | K5: 100 | L5: 0 | M5: 55 | N5: 🔥 Hot | O5: ⏳ New Fund | P5: 🔥 Hot Momentum | Q5: MOMENTUM_ONLY
A6: 2 | B6: Franklin India Arbitrage Fund - Growth | C6: Franklin Templeton Mutual Fund | D6: Arbitrage Fund | E6: 0.44 | F6: 1.5 | G6: 2.99 | H6: 6.13 | I6: 0 | J6: 0 | K6: 95.8 | L6: 0 | M6: 52.7 | N6: 🔥 Hot | O6: ⏳ New Fund | P6: 🔥 Hot Momentum | Q6: MOMENTUM_ONLY
A7: 3 | B7: Kotak Arbitrage Fund - Regular Plan - Growth | C7: Kotak Mahindra Mutual Fund | D7: Arbitrage Fund | E7: 0.44 | F7: 1.48 | G7: 2.9 | H7: 5.97 | I7: 6.4142848 | J7: 22.17 | K7: 88.3 | L7: 0 | M7: 48.6 | N7: ⭐ Strong | O7: 🔴 Not Qualified | P7: ⚠️ Watch | Q7: FULL
A8: 4 | B8: Union Arbitrage Fund - Regular Plan - Growth Option | C8: Union Mutual Fund | D8: Arbitrage Fund | E8: 0.49 | F8: 1.52 | G8: 2.91 | H8: 5.81 | I8: 6.1461257 | J8: 21.22 | K8: 85.9 | L8: 0 | M8: 47.3 | N8: ⭐ Strong | O8: 🔴 Not Qualified | P8: ⚠️ Watch | Q8: FULL
A9: 5 | B9: WhiteOak Capital Arbitrage Fund Regular Plan Growth | C9: WhiteOak Capital Mutual Fund | D9: Arbitrage Fund | E9: 0.39 | F9: 1.54 | G9: 3.08 | H9: 6.22 | I9: 0 | J9: 0 | K9: 83.1 | L9: 0 | M9: 45.7 | N9: ⭐ Strong | O9: ⏳ New Fund | P9: 🔥 Hot Momentum | Q9: MOMENTUM_ONLY
A10: 6 | B10: ICICI Prudential Arbitrage Fund - Growth | C10: ICICI Prudential Mutual Fund | D10: Arbitrage Fund | E10: 0.43 | F10: 1.46 | G10: 2.9 | H10: 5.94 | I10: 6.4142848 | J10: 21.81 | K10: 82.5 | L10: 0 | M10: 45.4 | N10: ⭐ Strong | O10: 🔴 Not Qualified | P10: ⚠️ Watch | Q10: FULL
A11: 7 | B11: LIC MF Arbitrage Fund-Regular Plan-Growth | C11: LIC Mutual Fund | D11: Arbitrage Fund | E11: 0.44 | F11: 1.48 | G11: 2.9 | H11: 5.85 | I11: 6.1838029 | J11: 20.65 | K11: 78.1 | L11: 0 | M11: 43 | N11: ⭐ Strong | O11: 🔴 Not Qualified | P11: ⚠️ Watch | Q11: FULL
A12: 8 | B12: Sundaram Arbitrage Fund (Formerly Know as Principal Arbitrage Fund) - Regular Plan - Growth | C12: Sundaram Mutual Fund | D12: Arbitrage Fund | E12: 0.42 | F12: 1.46 | G12: 2.91 | H12: 5.94 | I12: 6.2073444 | J12: 20.92 | K12: 76.7 | L12: 0 | M12: 42.2 | N12: ⭐ Strong | O12: 🔴 Not Qualified | P12: ⚠️ Watch | Q12: FULL
A13: 9 | B13: HDFC ARBITRAGE FUND - Regular Plan -Growth Option | C13: HDFC Mutual Fund | D13: Arbitrage Fund | E13: 0.42 | F13: 1.47 | G13: 2.84 | H13: 5.95 | I13: 6.3484838 | J13: 21.79 | K13: 73 | L13: 0 | M13: 40.1 | N13: 📈 Good | O13: 🔴 Not Qualified | P13: ⚠️ Watch | Q13: FULL
A14: 10 | B14: PGIM India Arbitrage Fund - Regular Plan - Growth | C14: PGIM India Mutual Fund | D14: Arbitrage Fund | E14: 0.46 | F14: 1.44 | G14: 2.86 | H14: 5.68 | I14: 6.0330137 | J14: 20.49 | K14: 72.8 | L14: 0 | M14: 40 | N14: 📈 Good | O14: 🔴 Not Qualified | P14: ⚠️ Watch | Q14: FULL
A15: 11 | B15: Parag Parikh Arbitrage Fund - Regular Plan Growth | C15: PPFAS Mutual Fund | D15: Arbitrage Fund | E15: 0.42 | F15: 1.43 | G15: 2.84 | H15: 5.97 | I15: 6.2732328 | J15: 0 | K15: 66.2 | L15: 0 | M15: 36.4 | N15: 📈 Good | O15: ⏳ New Fund | P15: 📈 Momentum Only | Q15: MOMENTUM_ONLY
A16: 12 | B16: Edelweiss Arbitrage Fund- Regular Plan- Growth Option | C16: Edelweiss Mutual Fund | D16: Arbitrage Fund | E16: 0.39 | F16: 1.45 | G16: 2.85 | H16: 5.86 | I16: 6.3014581 | J16: 21.65 | K16: 60.8 | L16: 0 | M16: 33.4 | N16: 📈 Good | O16: 🔴 Not Qualified | P16: 🔴 Avoid | Q16: FULL
... A38: 0 | B38: Capitalmind Arbitrage Fund-regular-Growth | C38: Capitalmind Mutual Fund | D38: Arbitrage Fund | E38: 0.37 | F38: 1.08 | G38: 0 | H38: 0 | I38: 0 | J38: 0 | K38: 0 | L38: 0 | M38: 0 | N38: ❌ N/A | O38: ❌ N/A | P38: ❌ Missing Data | Q38: MISSING

Sheet Balanced Hybrid Fund
A1: ✦ BALANCED HYBRID FUND ✦
A2: ="Dual Engine: 55% Momentum + 45% Quality | ✅ Full: "&COUNTIF(Q5:Q7,"FULL")&" | ⚠️ Momentum: "&COUNTIF(Q5:Q7,"MOMENTUM_ONLY")&" | ❌ Missing: "&COUNTIF(Q5:Q7,"MISSING")&" | Total: "&COUNTA(B5:B7)
E3: ◄ Momentum ► | H3: ◄ Long-Term ► | K3: ◄ Engine Scores ► | N3: ◄ Signals ►
A4: Rank | B4: Scheme Name | C4: AMC | D4: Asset Class | E4: 1M Return | F4: 3M Return | G4: 6M Return | H4: 1Y Return | I4: 2Y CAGR | J4: 3Y CAGR | K4: Engine 1 (Momentum) | L4: Engine 2 (Quality) | M4: Composite Score | N4: Momentum Signal | O4: Quality Signal | P4: Composite Signal | Q4: Data Status
A5: 1 | B5: 360 ONE Balanced Hybrid Fund - Regular Plan - Growth | C5: 360 ONE Mutual Fund | D5: Balanced Hybrid Fund | E5: 0.39 | F5: 5.11 | G5: 3.89 | H5: 5.5 | I5: 4.0865025 | J5: 0 | K5: 77.5 | L5: 0 | M5: 42.6 | N5: ⭐ Strong | O5: ⏳ New Fund | P5: 📈 Momentum Only | Q5: MOMENTUM_ONLY
A6: 2 | B6: WhiteOak Capital Balanced Hybrid Fund Regular Plan Growth | C6: WhiteOak Capital Mutual Fund | D6: Balanced Hybrid Fund | E6: 1.04 | F6: 5.1 | G6: 2.24 | H6: 4.98 | I6: 4.9761878 | J6: 0 | K6: 27.5 | L6: 0 | M6: 15.1 | N6: 📉 Weak | O6: ⏳ New Fund | P6: ⏳ New Fund | Q6: MOMENTUM_ONLY
A7: 0 | B7: ICICI Prudential Balanced Hybrid Fund - Growth | C7: ICICI Prudential Mutual Fund | D7: Balanced Hybrid Fund | E7: 0 | F7: 0 | G7: 0 | H7: 0 | I7: 0 | J7: 0 | K7: 0 | L7: 0 | M7: 0 | N7: ❌ N/A | O7: ❌ N/A | P7: ❌ Missing Data | Q7: MISSING

Sheet Conservative Hybrid Fund
A1: ✦ CONSERVATIVE HYBRID FUND ✦
A2: ="Dual Engine: 55% Momentum + 45% Quality | ✅ Full: "&COUNTIF(Q5:Q26,"FULL")&" | ⚠️ Momentum: "&COUNTIF(Q5:Q26,"MOMENTUM_ONLY")&" | ❌ Missing: "&COUNTIF(Q5:Q26,"MISSING")&" | Total: "&COUNTA(B5:B26)
E3: ◄ Momentum ► | H3: ◄ Long-Term ► | K3: ◄ Engine Scores ► | N3: ◄ Signals ►
A4: Rank | B4: Scheme Name | C4: AMC | D4: Asset Class | E4: 1M Return | F4: 3M Return | G4: 6M Return | H4: 1Y Return | I4: 2Y CAGR | J4: 3Y CAGR | K4: Engine 1 (Momentum) | L4: Engine 2 (Quality) | M4: Composite Score | N4: Momentum Signal | O4: Quality Signal | P4: Composite Signal | Q4: Data Status
A5: 1 | B5: Nippon India Conservative Hybrid Fund-Growth Plan | C5: Nippon India Mutual Fund | D5: Conservative Hybrid Fund | E5: 0.79 | F5: 2.99 | G5: 2.56 | H5: 7.22 | I5: 7.5313908 | J5: 26.82 | K5: 87.8 | L5: 0 | M5: 48.3 | N5: ⭐ Strong | O5: 🔴 Not Qualified | P5: ⚠️ Watch | Q5: FULL
A6: 2 | B6: Aditya Birla Sun Life Regular Savings Fund - Growth / Payment - Direct Plan | C6: Aditya Birla Sun Life Mutual Fund | D6: Conservative Hybrid Fund | E6: 0.67 | F6: 3.47 | G6: 2.52 | H6: 6.34 | I6: 7.5174404 | J6: 30.9 | K6: 87.5 | L6: 0 | M6: 48.1 | N6: ⭐ Strong | O6: 🔴 Not Qualified | P6: ⚠️ Watch | Q6: FULL
A7: 3 | B7: CANARA ROBECO CONSERVATIVE HYBRID FUND - REGULAR PLAN - GROWTH OPTION | C7: Canara Robeco Mutual Fund | D7: Conservative Hybrid Fund | E7: 0.81 | F7: 3.7 | G7: 2.6 | H7: 3.22 | I7: 4.6470258 | J7: 23.74 | K7: 81.2 | L7: 0 | M7: 44.7 | N7: ⭐ Strong | O7: 🔴 Not Qualified | P7: ⚠️ Watch | Q7: FULL
A8: 4 | B8: SBI Conservative Hybrid Fund - Regular Plan - Growth | C8: SBI Mutual Fund | D8: Conservative Hybrid Fund | E8: 0.55 | F8: 2.5 | G8: 2.82 | H8: 6.09 | I8: 5.6456341 | J8: 28.14 | K8: 79.5 | L8: 0 | M8: 43.7 | N8: ⭐ Strong | O8: 🔴 Not Qualified | P8: ⚠️ Watch | Q8: FULL
A9: 5 | B9: Aditya Birla Sun Life Regular Savings Fund - Growth / Payment - Regular Plan | C9: Aditya Birla Sun Life Mutual Fund | D9: Conservative Hybrid Fund | E9: 0.6 | F9: 3.25 | G9: 2.09 | H9: 5.4 | I9: 6.5692263 | J9: 27.42 | K9: 77.5 | L9: 0 | M9: 42.6 | N9: ⭐ Strong | O9: 🔴 Not Qualified | P9: ⚠️ Watch | Q9: FULL
A10: 6 | B10: BARODA BNP PARIBAS Conservative Hybrid Fund-Regular Plan-Growth Option | C10: Baroda BNP Paribas Mutual Fund | D10: Conservative Hybrid Fund | E10: 0.69 | F10: 2.82 | G10: 2.16 | H10: 4.89 | I10: 4.9142507 | J10: 24.35 | K10: 75 | L10: 0 | M10: 41.2 | N10: ⭐ Strong | O10: 🔴 Not Qualified | P10: ⚠️ Watch | Q10: FULL
A11: 7 | B11: BANDHAN Conservative Hybrid Fund - Regular Plan - Growth | C11: Bandhan Mutual Fund | D11: Conservative Hybrid Fund | E11: 0.87 | F11: 3.52 | G11: 1.39 | H11: 4.53 | I11: 4.0624812 | J11: 22.16 | K11: 72.5 | L11: 0 | M11: 39.9 | N11: 📈 Good | O11: 🔴 Not Qualified | P11: 🔴 Avoid | Q11: FULL
A12: 8 | B12: LIC MF Conservative Hybrid Fund-Regular Plan-Growth | C12: LIC Mutual Fund | D12: Conservative Hybrid Fund | E12: 0.81 | F12: 3.92 | G12: 1.51 | H12: 4.47 | I12: 4.2497002 | J12: 19.85 | K12: 72.2 | L12: 0 | M12: 39.7 | N12: 📈 Good | O12: 🔴 Not Qualified | P12: 🔴 Avoid | Q12: FULL
A13: 9 | B13: Parag Parikh Conservative Hybrid Fund - Regular Plan - Growth | C13: PPFAS Mutual Fund | D13: Conservative Hybrid Fund | E13: 0.22 | F13: 2.77 | G13: 1.76 | H13: 5.46 | I13: 6.2214668 | J13: 34.54 | K13: 60.8 | L13: 0 | M13: 33.4 | N13: 📈 Good | O13: 🔴 Not Qualified | P13: 🔴 Avoid | Q13: FULL
A14: 10 | B14: Kotak Debt Hybrid - Growth | C14: Kotak Mahindra Mutual Fund | D14: Conservative Hybrid Fund | E14: 0.55 | F14: 3.36 | G14: 0.97 | H14: 3.65 | I14: 3.754518 | J14: 26.74 | K14: 54 | L14: 0 | M14: 29.7 | N14: ➡️ Neutral | O14: 🔴 Not Qualified | P14: 🔴 Avoid | Q14: FULL
A15: 11 | B15: ICICI Prudential Regular Savings Fund - Direct Plan - Growth | C15: ICICI Prudential Mutual Fund | D15: Conservative Hybrid Fund | E15: 0.12 | F15: 2.31 | G15: 2.02 | H15: 5.06 | I15: 6.5457648 | J15: 31.53 | K15: 52.2 | L15: 0 | M15: 28.7 | N15: ➡️ Neutral | O15: 🔴 Not Qualified | P15: 🔴 Avoid | Q15: FULL
A16: 12 | B16: DSP Regular Savings Fund - Direct Plan - Growth | C16: DSP Mutual Fund | D16: Conservative Hybrid Fund | E16: 0.12 | F16: 2.3 | G16: 1.94 | H16: 4.77 | I16: 6.2073444 | J16: 30.19 | K16: 47.2 | L16: 0 | M16: 26 | N16: ➡️ Neutral | O16: 🔴 Not Qualified | P16: 🔴 Avoid | Q16: FULL
... A26: 0 | B26: Nippon India Conservative Hybrid Fund - Segregated Portfolio 2 - Growth Plan | C26: Nippon India Mutual Fund | D26: Conservative Hybrid Fund | E26: 0 | F26: 0 | G26: 0 | H26: 0 | I26: 0 | J26: 0 | K26: 0 | L26: 0 | M26: 0 | N26: ❌ N/A | O26: ❌ N/A | P26: ❌ Missing Data | Q26: MISSING

Sheet Dynamic Asset Allocation Or Bal
A1: ✦ DYNAMIC ASSET ALLOCATION OR BALANCED ADVANTAGE ✦
A2: ="Dual Engine: 55% Momentum + 45% Quality | ✅ Full: "&COUNTIF(Q5:Q40,"FULL")&" | ⚠️ Momentum: "&COUNTIF(Q5:Q40,"MOMENTUM_ONLY")&" | ❌ Missing: "&COUNTIF(Q5:Q40,"MISSING")&" | Total: "&COUNTA(B5:B40)
E3: ◄ Momentum ► | H3: ◄ Long-Term ► | K3: ◄ Engine Scores ► | N3: ◄ Signals ►
A4: Rank | B4: Scheme Name | C4: AMC | D4: Asset Class | E4: 1M Return | F4: 3M Return | G4: 6M Return | H4: 1Y Return | I4: 2Y CAGR | J4: 3Y CAGR | K4: Engine 1 (Momentum) | L4: Engine 2 (Quality) | M4: Composite Score | N4: Momentum Signal | O4: Quality Signal | P4: Composite Signal | Q4: Data Status
A5: 1 | B5: ICICI Prudential Balanced Advantage Fund - Growth | C5: ICICI Prudential Mutual Fund | D5: Dynamic Asset Allocation Or Balanced Advantage | E5: 2.24 | F5: 6.21 | G5: 2.53 | H5: 8.44 | I5: 7.2427154 | J5: 41.27 | K5: 93.2 | L5: 0 | M5: 51.3 | N5: 🔥 Hot | O5: 🔴 Not Qualified | P5: ⚠️ Watch | Q5: FULL
A6: 2 | B6: Aditya Birla Sun Life Balanced Advantage Fund - Regular Plan - Growth Option | C6: Aditya Birla Sun Life Mutual Fund | D6: Dynamic Asset Allocation Or Balanced Advantage | E6: 1.54 | F6: 5.57 | G6: 3.55 | H6: 8.34 | I6: 6.6255129 | J6: 39.77 | K6: 89.7 | L6: 0 | M6: 49.3 | N6: ⭐ Strong | O6: 🔴 Not Qualified | P6: ⚠️ Watch | Q6: FULL
A7: 3 | B7: LIC MF Balanced Advantage Fund-Regular Plan-Growth | C7: LIC Mutual Fund | D7: Dynamic Asset Allocation Or Balanced Advantage | E7: 3.71 | F7: 7.7 | G7: 3.23 | H7: 4.2 | I7: 3.8701112 | J7: 26.24 | K7: 85.1 | L7: 0 | M7: 46.8 | N7: ⭐ Strong | O7: 🔴 Not Qualified | P7: ⚠️ Watch | Q7: FULL
A8: 4 | B8: UTI - Unit Linked Insurance Plan | C8: UTI Mutual Fund | D8: Dynamic Asset Allocation Or Balanced Advantage | E8: 1.83 | F8: 6.51 | G8: 4.04 | H8: 3.98 | I8: 5.1047097 | J8: 27.02 | K8: 84.3 | L8: 0 | M8: 46.3 | N8: ⭐ Strong | O8: 🔴 Not Qualified | P8: ⚠️ Watch | Q8: FULL
A9: 5 | B9: Baroda BNP Paribas Balanced Advantage Fund-Regular Plan -Growth Option | C9: Baroda BNP Paribas Mutual Fund | D9: Dynamic Asset Allocation Or Balanced Advantage | E9: 1.61 | F9: 4.08 | G9: 2.77 | H9: 8.55 | I9: 6.212052 | J9: 42.72 | K9: 83.7 | L9: 0 | M9: 46 | N9: ⭐ Strong | O9: 🔴 Not Qualified | P9: ⚠️ Watch | Q9: FULL
A10: 6 | B10: Edelweiss Balanced Advantage Fund - Regular Plan - Growth Option | C10: Edelweiss Mutual Fund | D10: Dynamic Asset Allocation Or Balanced Advantage | E10: 1.9 | F10: 4.61 | G10: 1.63 | H10: 6.8 | I10: 3.7063161 | J10: 35.24 | K10: 82.8 | L10: 0 | M10: 45.5 | N10: ⭐ Strong | O10: 🔴 Not Qualified | P10: ⚠️ Watch | Q10: FULL
A11: 7 | B11: Motilal Oswal Balanced Advantage Fund (MOFDYNAMIC) - Regular Plan - Growth Option | C11: Motilal Oswal Mutual Fund | D11: Dynamic Asset Allocation Or Balanced Advantage | E11: 5.42 | F11: 9.34 | G11: 6.19 | H11: -0.52 | I11: -5.0684457 | J11: 8.22 | K11: 79 | L11: 0 | M11: 43.4 | N11: ⭐ Strong | O11: 🔴 Not Qualified | P11: ⚠️ Watch | Q11: FULL
A12: 8 | B12: WhiteOak Capital Balanced Advantage Fund Regular Plan Growth | C12: WhiteOak Capital Mutual Fund | D12: Dynamic Asset Allocation Or Balanced Advantage | E12: 1.17 | F12: 5.74 | G12: 2.46 | H12: 4.59 | I12: 5.6692954 | J12: 37.96 | K12: 75 | L12: 0 | M12: 41.2 | N12: ⭐ Strong | O12: 🔴 Not Qualified | P12: ⚠️ Watch | Q12: FULL
A13: 9 | B13: Unifi Dynamic Asset Allocation Fund - Regular Growth | C13: Unifi Mutual Fund | D13: Dynamic Asset Allocation Or Balanced Advantage | E13: 0.76 | F13: 2.42 | G13: 3.73 | H13: 7.62 | I13: 0 | J13: 0 | K13: 73.4 | L13: 0 | M13: 40.4 | N13: 📈 Good | O13: ⏳ New Fund | P13: 📈 Momentum Only | Q13: MOMENTUM_ONLY
A14: 10 | B14: Bajaj Finserv Balanced Advantage Fund-Regular Plan-Growth | C14: Bajaj Finserv Mutual Fund | D14: Dynamic Asset Allocation Or Balanced Advantage | E14: 1.24 | F14: 5.81 | G14: 0.71 | H14: 6.44 | I14: 2.6304049 | J14: 0 | K14: 73.2 | L14: 0 | M14: 40.3 | N14: 📈 Good | O14: ⏳ New Fund | P14: 📈 Momentum Only | Q14: MOMENTUM_ONLY
A15: 11 | B15: BANDHAN Balanced Advantage Fund Regular Plan Growth | C15: Bandhan Mutual Fund | D15: Dynamic Asset Allocation Or Balanced Advantage | E15: 0.62 | F15: 4.18 | G15: 2.37 | H15: 5.84 | I15: 4.4413711 | J15: 32.26 | K15: 68.4 | L15: 0 | M15: 37.6 | N15: 📈 Good | O15: 🔴 Not Qualified | P15: 🔴 Avoid | Q15: FULL
A16: 12 | B16: Kotak Balanced Advantage Fund - Regular Plan - Payout of Income Distribution cum capital withdrawal option Option | C16: Kotak Mahindra Mutual Fund | D16: Dynamic Asset Allocation Or Balanced Advantage | E16: 0.86 | F16: 4.77 | G16: 0.96 | H16: 4.68 | I16: 4.158533 | J16: 32.23 | K16: 63.8 | L16: 0 | M16: 35.1 | N16: 📈 Good | O16: 🔴 Not Qualified | P16: 🔴 Avoid | Q16: FULL
... A40: 0 | B40: The Wealth Company Balanced Advantage Fund - Regular Growth | C40: The Wealth Company Mutual Fund | D40: Dynamic Asset Allocation Or Balanced Advantage | E40: 1.36 | F40: 2.35 | G40: 0 | H40: 0 | I40: 0 | J40: 0 | K40: 0 | L40: 0 | M40: 0 | N40: ❌ N/A | O40: ❌ N/A | P40: ❌ Missing Data | Q40: MISSING

Sheet Equity Savings
A1: ✦ EQUITY SAVINGS ✦
A2: ="Dual Engine: 55% Momentum + 45% Quality | ✅ Full: "&COUNTIF(Q5:Q29,"FULL")&" | ⚠️ Momentum: "&COUNTIF(Q5:Q29,"MOMENTUM_ONLY")&" | ❌ Missing: "&COUNTIF(Q5:Q29,"MISSING")&" | Total: "&COUNTA(B5:B29)
E3: ◄ Momentum ► | H3: ◄ Long-Term ► | K3: ◄ Engine Scores ► | N3: ◄ Signals ►
A4: Rank | B4: Scheme Name | C4: AMC | D4: Asset Class | E4: 1M Return | F4: 3M Return | G4: 6M Return | H4: 1Y Return | I4: 2Y CAGR | J4: 3Y CAGR | K4: Engine 1 (Momentum) | L4: Engine 2 (Quality) | M4: Composite Score | N4: Momentum Signal | O4: Quality Signal | P4: Composite Signal | Q4: Data Status
A5: 1 | B5: Edelweiss Equity Savings Fund - Regular Plan - Growth Option | C5: Edelweiss Mutual Fund | D5: Equity Savings | E5: 1.34 | F5: 3.73 | G5: 4.13 | H5: 8.12 | I5: 7.856386 | J5: 35.86 | K5: 99.5 | L5: 0 | M5: 54.8 | N5: 🔥 Hot | O5: 🔴 Not Qualified | P5: ⚠️ Watch | Q5: FULL
A6: 2 | B6: Axis Equity Savings Fund - Regular Plan - Growth | C6: Axis Mutual Fund | D6: Equity Savings | E6: 1 | F6: 4.3 | G6: 2.28 | H6: 5.81 | I6: 4.5896744 | J6: 29.72 | K6: 82.5 | L6: 0 | M6: 45.4 | N6: ⭐ Strong | O6: 🔴 Not Qualified | P6: ⚠️ Watch | Q6: FULL
A7: 3 | B7: WhiteOak Capital Equity Savings Fund Regular Plan Growth | C7: WhiteOak Capital Mutual Fund | D7: Equity Savings | E7: 0.73 | F7: 3.39 | G7: 2.15 | H7: 6.81 | I7: 0 | J7: 0 | K7: 82.3 | L7: 0 | M7: 45.2 | N7: ⭐ Strong | O7: ⏳ New Fund | P7: 🔥 Hot Momentum | Q7: MOMENTUM_ONLY
A8: 4 | B8: Baroda BNP Paribas Equity Savings Fund - Regular Plan - Growth | C8: Baroda BNP Paribas Mutual Fund | D8: Equity Savings | E8: 1.37 | F8: 3.26 | G8: 2.1 | H8: 5.81 | I8: 5.5604092 | J8: 29.98 | K8: 78.6 | L8: 0 | M8: 43.3 | N8: ⭐ Strong | O8: 🔴 Not Qualified | P8: ⚠️ Watch | Q8: FULL
A9: 5 | B9: quant Equity Savings Fund - Growth Option - Regular Plan | C9: quant Mutual Fund | D9: Equity Savings | E9: -0.8 | F9: 3.88 | G9: 4.58 | H9: 6.49 | I9: 0 | J9: 0 | K9: 75.7 | L9: 0 | M9: 41.6 | N9: ⭐ Strong | O9: ⏳ New Fund | P9: 📈 Momentum Only | Q9: MOMENTUM_ONLY
A10: 5 | B10: LIC MF Equity Savings Fund-Regular Plan-Growth | C10: LIC Mutual Fund | D10: Equity Savings | E10: 2.15 | F10: 2.52 | G10: 3.14 | H10: 4.02 | I10: 5.3043209 | J10: 28.01 | K10: 75.7 | L10: 0 | M10: 41.6 | N10: ⭐ Strong | O10: 🔴 Not Qualified | P10: ⚠️ Watch | Q10: FULL
A11: 7 | B11: Mahindra Manulife Equity Savings Fund - Regular Plan - Growth | C11: Mahindra Manulife Mutual Fund | D11: Equity Savings | E11: 0.71 | F11: 3.47 | G11: 1.74 | H11: 6.56 | I11: 4.8570455 | J11: 28.44 | K11: 74.1 | L11: 0 | M11: 40.8 | N11: 📈 Good | O11: 🔴 Not Qualified | P11: ⚠️ Watch | Q11: FULL
A12: 8 | B12: Aditya Birla Sun Life Equity Savings Fund - Regular Plan - Growth | C12: Aditya Birla Sun Life Mutual Fund | D12: Equity Savings | E12: 0.69 | F12: 2.67 | G12: 2.09 | H12: 6.02 | I12: 6.4941313 | J12: 26.17 | K12: 66.6 | L12: 0 | M12: 36.6 | N12: 📈 Good | O12: 🔴 Not Qualified | P12: 🔴 Avoid | Q12: FULL
A13: 9 | B13: Kotak Equity Savings Fund - Regular - Growth | C13: Kotak Mahindra Mutual Fund | D13: Equity Savings | E13: 1.04 | F13: 2.56 | G13: 1.51 | H13: 6.1 | I13: 5.0190459 | J13: 32.3 | K13: 63.9 | L13: 0 | M13: 35.1 | N13: 📈 Good | O13: 🔴 Not Qualified | P13: 🔴 Avoid | Q13: FULL
A14: 9 | B14: Kotak Equity Savings Fund - Regular - Monthly Payout of Income Distribution cum capital withdrawal option | C14: Kotak Mahindra Mutual Fund | D14: Equity Savings | E14: 1.04 | F14: 2.56 | G14: 1.51 | H14: 6.1 | I14: 5.0190459 | J14: 32.3 | K14: 63.9 | L14: 0 | M14: 35.1 | N14: 📈 Good | O14: 🔴 Not Qualified | P14: 🔴 Avoid | Q14: FULL
A15: 11 | B15: Union Equity Savings Fund - Regular Plan - Growth Option | C15: Union Mutual Fund | D15: Equity Savings | E15: 0.52 | F15: 3.67 | G15: 1.45 | H15: 4.41 | I15: 3.8364098 | J15: 22.96 | K15: 57 | L15: 0 | M15: 31.4 | N15: ➡️ Neutral | O15: 🔴 Not Qualified | P15: 🔴 Avoid | Q15: FULL
A16: 12 | B16: PGIM India Equity Savings Fund - Growth Option | C16: PGIM India Mutual Fund | D16: Equity Savings | E16: 0.51 | F16: 2.99 | G16: 1.54 | H16: 4.12 | I16: 4.8093507 | J16: 20.35 | K16: 54.1 | L16: 0 | M16: 29.8 | N16: ➡️ Neutral | O16: 🔴 Not Qualified | P16: 🔴 Avoid | Q16: FULL
... A29: 0 | B29: Nippon India Equity Savings Fund - Segregated Portfolio 2 - Growth Plan - Growth Option | C29: Nippon India Mutual Fund | D29: Equity Savings | E29: 0 | F29: 0 | G29: 0 | H29: 0 | I29: 0 | J29: 0 | K29: 0 | L29: 0 | M29: 0 | N29: ❌ N/A | O29: ❌ N/A | P29: ❌ Missing Data | Q29: MISSING

Sheet Multi Asset Allocation
A1: ✦ MULTI ASSET ALLOCATION ✦
A2: ="Dual Engine: 55% Momentum + 45% Quality | ✅ Full: "&COUNTIF(Q5:Q36,"FULL")&" | ⚠️ Momentum: "&COUNTIF(Q5:Q36,"MOMENTUM_ONLY")&" | ❌ Missing: "&COUNTIF(Q5:Q36,"MISSING")&" | Total: "&COUNTA(B5:B36)
E3: ◄ Momentum ► | H3: ◄ Long-Term ► | K3: ◄ Engine Scores ► | N3: ◄ Signals ►
A4: Rank | B4: Scheme Name | C4: AMC | D4: Asset Class | E4: 1M Return | F4: 3M Return | G4: 6M Return | H4: 1Y Return | I4: 2Y CAGR | J4: 3Y CAGR | K4: Engine 1 (Momentum) | L4: Engine 2 (Quality) | M4: Composite Score | N4: Momentum Signal | O4: Quality Signal | P4: Composite Signal | Q4: Data Status
A5: 1 | B5: Nippon India Multi Asset Allocation Fund - Regular Plan - Growth Option | C5: Nippon India Mutual Fund | D5: Multi Asset Allocation | E5: 3.11 | F5: 4.03 | G5: 2.85 | H5: 17.08 | I5: 13.274004 | J5: 69.63 | K5: 87.5 | L5: 75 | M5: 81.9 | N5: ⭐ Strong | O5: ⭐ Strong | P5: ⭐ Strong Buy | Q5: FULL
A6: 2 | B6: quant Multi Asset Allocation Fund-GROWTH OPTION - Regular Plan | C6: quant Mutual Fund | D6: Multi Asset Allocation | E6: -0.87 | F6: 2.25 | G6: 3.36 | H6: 19.45 | I6: 13.035393 | J6: 80.47 | K6: 58.3 | L6: 85 | M6: 70.3 | N6: ➡️ Neutral | O6: ⭐ Strong | P6: 🏛️ Quality Hold | Q6: FULL
A7: 3 | B7: WhiteOak Capital Multi Asset Allocation Fund Regular Plan Growth | C7: WhiteOak Capital Mutual Fund | D7: Multi Asset Allocation | E7: 2.22 | F7: 4.23 | G7: 4.26 | H7: 13.93 | I7: 14.328474 | J7: 57.4 | K7: 82.1 | L7: 52.5 | M7: 68.8 | N7: ⭐ Strong | O7: ➡️ Average | P7: 📈 Momentum Play | Q7: FULL
A8: 4 | B8: Aditya Birla Sun Life Multi Asset Allocation Fund-Regular Growth | C8: Aditya Birla Sun Life Mutual Fund | D8: Multi Asset Allocation | E8: 1.87 | F8: 3.99 | G8: 1.99 | H8: 16.63 | I8: 12.151683 | J8: 56.54 | K8: 69.7 | L8: 31.2 | M8: 52.4 | N8: 📈 Good | O8: ⚠️ Below Avg | P8: ⚠️ Watch | Q8: FULL
A9: 5 | B9: Bandhan Multi Asset Allocation Fund - Regular Plan - Growth | C9: Bandhan Mutual Fund | D9: Multi Asset Allocation | E9: 2.33 | F9: 3.03 | G9: 3.57 | H9: 16.86 | I9: 12.387722 | J9: 0 | K9: 80.5 | L9: 0 | M9: 44.3 | N9: ⭐ Strong | O9: ⏳ New Fund | P9: 🔥 Hot Momentum | Q9: MOMENTUM_ONLY
A10: 6 | B10: Bank of India Multi Asset Allocation Fund-Regular Plan-Growth | C10: Bank of India Mutual Fund | D10: Multi Asset Allocation | E10: 2.27 | F10: 3.85 | G10: 3.74 | H10: 14.18 | I10: 8.7336195 | J10: 0 | K10: 76.5 | L10: 0 | M10: 42.1 | N10: ⭐ Strong | O10: ⏳ New Fund | P10: 📈 Momentum Only | Q10: MOMENTUM_ONLY
A11: 7 | B11: Canara Robeco Multi Asset Allocation Fund - Regular Plan - Growth | C11: Canara Robeco Mutual Fund | D11: Multi Asset Allocation | E11: 3.08 | F11: 4.7 | G11: 1.88 | H11: 12.35 | I11: 0 | J11: 0 | K11: 75.6 | L11: 0 | M11: 41.6 | N11: ⭐ Strong | O11: ⏳ New Fund | P11: 📈 Momentum Only | Q11: MOMENTUM_ONLY
A12: 8 | B12: Mahindra Manulife Multi Asset Allocation Fund- Regular Plan - Growth | C12: Mahindra Manulife Mutual Fund | D12: Multi Asset Allocation | E12: 1.85 | F12: 4.22 | G12: 2.49 | H12: 17.17 | I12: 12.48111 | J12: 0 | K12: 75.1 | L12: 0 | M12: 41.3 | N12: ⭐ Strong | O12: ⏳ New Fund | P12: 📈 Momentum Only | Q12: MOMENTUM_ONLY
A13: 9 | B13: Axis Multi Asset Allocation Fund - Regular Plan - Growth Option | C13: Axis Mutual Fund | D13: Multi Asset Allocation | E13: 2.64 | F13: 4.24 | G13: 0.41 | H13: 14.64 | I13: 9.2520023 | J13: 49.62 | K13: 70.9 | L13: 0 | M13: 39 | N13: 📈 Good | O13: 🔴 Not Qualified | P13: 🔴 Avoid | Q13: FULL
A14: 10 | B14: Kotak Multi Asset Allocation Fund - Regular Plan - Growth Option | C14: Kotak Mahindra Mutual Fund | D14: Multi Asset Allocation | E14: 2.56 | F14: 2.32 | G14: 1.44 | H14: 22.27 | I14: 12.445542 | J14: 0 | K14: 64.4 | L14: 0 | M14: 35.4 | N14: 📈 Good | O14: ⏳ New Fund | P14: 📈 Momentum Only | Q14: MOMENTUM_ONLY
A15: 11 | B15: DSP Multi Asset Allocation Fund - Regular - Growth | C15: DSP Mutual Fund | D15: Multi Asset Allocation | E15: 1.65 | F15: 2.16 | G15: 2.17 | H15: 19.64 | I15: 15.360305 | J15: 0 | K15: 58.8 | L15: 0 | M15: 32.3 | N15: ➡️ Neutral | O15: ⏳ New Fund | P15: ⏳ New Fund | Q15: MOMENTUM_ONLY
A16: 12 | B16: Franklin India Multi Asset Allocation Fund- Growth | C16: Franklin Templeton Mutual Fund | D16: Multi Asset Allocation | E16: 2.55 | F16: 3.68 | G16: -0.19 | H16: 11.88 | I16: 0 | J16: 0 | K16: 55.6 | L16: 0 | M16: 30.6 | N16: ➡️ Neutral | O16: ⏳ New Fund | P16: ⏳ New Fund | Q16: MOMENTUM_ONLY
... A36: 0 | B36: Capitalmind Multi Asset Allocation Fund-Regular-Growth | C36: Capitalmind Mutual Fund | D36: Multi Asset Allocation | E36: 2.61 | F36: -2.18 | G36: 0 | H36: 0 | I36: 0 | J36: 0 | K36: 0 | L36: 0 | M36: 0 | N36: ❌ N/A | O36: ❌ N/A | P36: ❌ Missing Data | Q36: MISSING

Sheet 📊 CONSOLIDATED
A1: 📊 CONSOLIDATED VIEW — ALL FUNDS RANKED
A2: ="All Funds Consolidated | 55% Momentum + 45% Quality | ✅ Full: "&COUNTIF($U:$U,"FULL")&" | ⚠️ Momentum: "&COUNTIF($U:$U,"MOMENTUM_ONLY")&" | ❌ Missing: "&COUNTIF($U:$U,"MISSING")&" | Total: "&COUNTA(B5:B184)
F3: ◄ Momentum ► | I3: ◄ Long-Term ► | L3: ◄ Engine Scores ► | O3: ◄ Rank in Asset Class ► | R3: ◄ Signals ►
A4: Rank | B4: Scheme Name | C4: AMC | D4: Category | E4: Asset Class | F4: 1M Return | G4: 3M Return | H4: 6M Return | I4: 1Y Return | J4: 2Y CAGR | K4: 3Y CAGR | L4: Engine 1 (Momentum) | M4: Engine 2 (Quality) | N4: Composite Score | O4: E1 Rank (in Asset) | P4: E2 Rank (in Asset) | Q4: Comp Rank (in Asset) | R4: Momentum Signal | S4: Quality Signal | T4: Composite Signal | U4: Data Status
A5: 1 | B5: Nippon India Multi Asset Allocation Fund - Regular Plan - Growth Option | C5: Nippon India Mutual Fund | D5: Multi Asset Allocation | E5: Multi Asset Allocation | F5: 3.11 | G5: 4.03 | H5: 2.85 | I5: 17.08 | J5: 13.274004 | K5: 69.63 | L5: 87.5 | M5: 75 | N5: 81.9 | O5: =COUNTIFS($E:$E,$E5,$L:$L,">"&$L5)+1 | P5: =COUNTIFS($E:$E,$E5,$M:$M,">"&$M5)+1 | Q5: =COUNTIFS($E:$E,$E5,$N:$N,">"&$N5)+1 | R5: ⭐ Strong | S5: ⭐ Strong | T5: ⭐ Strong Buy | U5: FULL
A6: 2 | B6: quant Multi Asset Allocation Fund-GROWTH OPTION - Regular Plan | C6: quant Mutual Fund | D6: Multi Asset Allocation | E6: Multi Asset Allocation | F6: -0.87 | G6: 2.25 | H6: 3.36 | I6: 19.45 | J6: 13.035393 | K6: 80.47 | L6: 58.3 | M6: 85 | N6: 70.3 | O6: =COUNTIFS($E:$E,$E6,$L:$L,">"&$L6)+1 | P6: =COUNTIFS($E:$E,$E6,$M:$M,">"&$M6)+1 | Q6: =COUNTIFS($E:$E,$E6,$N:$N,">"&$N6)+1 | R6: ➡️ Neutral | S6: ⭐ Strong | T6: 🏛️ Quality Hold | U6: FULL
A7: 3 | B7: WhiteOak Capital Multi Asset Allocation Fund Regular Plan Growth | C7: WhiteOak Capital Mutual Fund | D7: Multi Asset Allocation | E7: Multi Asset Allocation | F7: 2.22 | G7: 4.23 | H7: 4.26 | I7: 13.93 | J7: 14.328474 | K7: 57.4 | L7: 82.1 | M7: 52.5 | N7: 68.8 | O7: =COUNTIFS($E:$E,$E7,$L:$L,">"&$L7)+1 | P7: =COUNTIFS($E:$E,$E7,$M:$M,">"&$M7)+1 | Q7: =COUNTIFS($E:$E,$E7,$N:$N,">"&$N7)+1 | R7: ⭐ Strong | S7: ➡️ Average | T7: 📈 Momentum Play | U7: FULL
A8: 4 | B8: BANK OF INDIA MID & SMALL CAP EQUITY & DEBT FUND - REGULAR PLAN GROWTH | C8: Bank of India Mutual Fund | D8: Aggressive Hybrid Fund | E8: Aggressive Hybrid Fund | F8: 2.99 | G8: 7.47 | H8: 11.66 | I8: 15 | J8: 5.5035544 | K8: 63.04 | L8: 100 | M8: 0 | N8: 55 | O8: =COUNTIFS($E:$E,$E8,$L:$L,">"&$L8)+1 | P8: =COUNTIFS($E:$E,$E8,$M:$M,">"&$M8)+1 | Q8: =COUNTIFS($E:$E,$E8,$N:$N,">"&$N8)+1 | R8: 🔥 Hot | S8: 🔴 Not Qualified | T8: ✅ Buy | U8: FULL
A9: 5 | B9: Edelweiss Equity Savings Fund - Regular Plan - Growth Option | C9: Edelweiss Mutual Fund | D9: Equity Savings | E9: Equity Savings | F9: 1.34 | G9: 3.73 | H9: 4.13 | I9: 8.12 | J9: 7.856386 | K9: 35.86 | L9: 99.5 | M9: 0 | N9: 54.8 | O9: =COUNTIFS($E:$E,$E9,$L:$L,">"&$L9)+1 | P9: =COUNTIFS($E:$E,$E9,$M:$M,">"&$M9)+1 | Q9: =COUNTIFS($E:$E,$E9,$N:$N,">"&$N9)+1 | R9: 🔥 Hot | S9: 🔴 Not Qualified | T9: ⚠️ Watch | U9: FULL
A10: 6 | B10: Navi Aggressive Hybrid Fund - Regular Plan - Growth | C10: Navi Mutual Fund | D10: Aggressive Hybrid Fund | E10: Aggressive Hybrid Fund | F10: 2.45 | G10: 8.71 | H10: 6.51 | I10: 10.71 | J10: 5.446669 | K10: 37.75 | L10: 95.4 | M10: 0 | N10: 52.5 | O10: =COUNTIFS($E:$E,$E10,$L:$L,">"&$L10)+1 | P10: =COUNTIFS($E:$E,$E10,$M:$M,">"&$M10)+1 | Q10: =COUNTIFS($E:$E,$E10,$N:$N,">"&$N10)+1 | R10: 🔥 Hot | S10: 🔴 Not Qualified | T10: ⚠️ Watch | U10: FULL
A11: 7 | B11: Aditya Birla Sun Life Multi Asset Allocation Fund-Regular Growth | C11: Aditya Birla Sun Life Mutual Fund | D11: Multi Asset Allocation | E11: Multi Asset Allocation | F11: 1.87 | G11: 3.99 | H11: 1.99 | I11: 16.63 | J11: 12.151683 | K11: 56.54 | L11: 69.7 | M11: 31.2 | N11: 52.4 | O11: =COUNTIFS($E:$E,$E11,$L:$L,">"&$L11)+1 | P11: =COUNTIFS($E:$E,$E11,$M:$M,">"&$M11)+1 | Q11: =COUNTIFS($E:$E,$E11,$N:$N,">"&$N11)+1 | R11: 📈 Good | S11: ⚠️ Below Avg | T11: ⚠️ Watch | U11: FULL
A12: 8 | B12: ICICI Prudential Balanced Advantage Fund - Growth | C12: ICICI Prudential Mutual Fund | D12: Dynamic Asset Allocation Or Balanced Advantage | E12: Dynamic Asset Allocation Or Balanced Advantage | F12: 2.24 | G12: 6.21 | H12: 2.53 | I12: 8.44 | J12: 7.2427154 | K12: 41.27 | L12: 93.2 | M12: 0 | N12: 51.3 | O12: =COUNTIFS($E:$E,$E12,$L:$L,">"&$L12)+1 | P12: =COUNTIFS($E:$E,$E12,$M:$M,">"&$M12)+1 | Q12: =COUNTIFS($E:$E,$E12,$N:$N,">"&$N12)+1 | R12: 🔥 Hot | S12: 🔴 Not Qualified | T12: ⚠️ Watch | U12: FULL
A13: 9 | B13: LIC MF Aggressive Hybrid Fund-Regular Plan-Growth | C13: LIC Mutual Fund | D13: Aggressive Hybrid Fund | E13: Aggressive Hybrid Fund | F13: 3.72 | G13: 7.17 | H13: 3.77 | I13: 5.46 | J13: 3.4263023 | K13: 39.39 | L13: 90.8 | M13: 0 | N13: 49.9 | O13: =COUNTIFS($E:$E,$E13,$L:$L,">"&$L13)+1 | P13: =COUNTIFS($E:$E,$E13,$M:$M,">"&$M13)+1 | Q13: =COUNTIFS($E:$E,$E13,$N:$N,">"&$N13)+1 | R13: 🔥 Hot | S13: 🔴 Not Qualified | T13: ⚠️ Watch | U13: FULL
A14: 10 | B14: Aditya Birla Sun Life Balanced Advantage Fund - Regular Plan - Growth Option | C14: Aditya Birla Sun Life Mutual Fund | D14: Dynamic Asset Allocation Or Balanced Advantage | E14: Dynamic Asset Allocation Or Balanced Advantage | F14: 1.54 | G14: 5.57 | H14: 3.55 | I14: 8.34 | J14: 6.6255129 | K14: 39.77 | L14: 89.7 | M14: 0 | N14: 49.3 | O14: =COUNTIFS($E:$E,$E14,$L:$L,">"&$L14)+1 | P14: =COUNTIFS($E:$E,$E14,$M:$M,">"&$M14)+1 | Q14: =COUNTIFS($E:$E,$E14,$N:$N,">"&$N14)+1 | R14: ⭐ Strong | S14: 🔴 Not Qualified | T14: ⚠️ Watch | U14: FULL
A15: 11 | B15: Bandhan Aggressive Hybrid Fund-Regular Plan Growth | C15: Bandhan Mutual Fund | D15: Aggressive Hybrid Fund | E15: Aggressive Hybrid Fund | F15: 2.04 | G15: 6.98 | H15: 3.55 | I15: 9.58 | J15: 7.9953703 | K15: 50.07 | L15: 88.8 | M15: 0 | N15: 48.9 | O15: =COUNTIFS($E:$E,$E15,$L:$L,">"&$L15)+1 | P15: =COUNTIFS($E:$E,$E15,$M:$M,">"&$M15)+1 | Q15: =COUNTIFS($E:$E,$E15,$N:$N,">"&$N15)+1 | R15: ⭐ Strong | S15: 🔴 Not Qualified | T15: ⚠️ Watch | U15: FULL
A16: 12 | B16: Kotak Arbitrage Fund - Regular Plan - Growth | C16: Kotak Mahindra Mutual Fund | D16: Arbitrage Fund | E16: Arbitrage Fund | F16: 0.44 | G16: 1.48 | H16: 2.9 | I16: 5.97 | J16: 6.4142848 | K16: 22.17 | L16: 88.3 | M16: 0 | N16: 48.6 | O16: =COUNTIFS($E:$E,$E16,$L:$L,">"&$L16)+1 | P16: =COUNTIFS($E:$E,$E16,$M:$M,">"&$M16)+1 | Q16: =COUNTIFS($E:$E,$E16,$N:$N,">"&$N16)+1 | R16: ⭐ Strong | S16: 🔴 Not Qualified | T16: ⚠️ Watch | U16: FULL
... A184: 180 | B184: The Wealth Company Balanced Advantage Fund - Regular Growth | C184: The Wealth Company Mutual Fund | D184: Dynamic Asset Allocation Or Balanced Advantage | E184: Dynamic Asset Allocation Or Balanced Advantage | F184: 1.36 | G184: 2.35 | H184: 0 | I184: 0 | J184: 0 | K184: 0 | L184: 0 | M184: 0 | N184: 0 | O184: =COUNTIFS($E:$E,$E184,$L:$L,">"&$L184)+1 | P184: =COUNTIFS($E:$E,$E184,$M:$M,">"&$M184)+1 | Q184: =COUNTIFS($E:$E,$E184,$N:$N,">"&$N184)+1 | R184: ❌ N/A | S184: ❌ N/A | T184: ❌ Missing Data | U184: MISSING
